[2025-01-08T11:38:27.933+0000] {local_task_job_runner.py:123} INFO - ::group::Pre task execution logs
[2025-01-08T11:38:27.953+0000] {taskinstance.py:2613} INFO - Dependencies all met for dep_context=non-requeueable deps ti=<TaskInstance: task_dependency_airbyte_dag.test_sources_caches scheduled__2024-03-01T00:00:00+00:00 [queued]>
[2025-01-08T11:38:27.962+0000] {taskinstance.py:2613} INFO - Dependencies all met for dep_context=requeueable deps ti=<TaskInstance: task_dependency_airbyte_dag.test_sources_caches scheduled__2024-03-01T00:00:00+00:00 [queued]>
[2025-01-08T11:38:27.962+0000] {taskinstance.py:2866} INFO - Starting attempt 2 of 2
[2025-01-08T11:38:27.980+0000] {taskinstance.py:2889} INFO - Executing <Task(PythonVirtualenvOperator): test_sources_caches> on 2024-03-01 00:00:00+00:00
[2025-01-08T11:38:27.986+0000] {logging_mixin.py:190} WARNING - /home/***/.local/lib/python3.12/site-packages/***/task/task_runner/standard_task_runner.py:70 DeprecationWarning: This process (pid=9146) is multi-threaded, use of fork() may lead to deadlocks in the child.
[2025-01-08T11:38:27.987+0000] {standard_task_runner.py:72} INFO - Started process 9147 to run task
[2025-01-08T11:38:27.987+0000] {standard_task_runner.py:104} INFO - Running: ['***', 'tasks', 'run', 'task_dependency_airbyte_dag', 'test_sources_caches', 'scheduled__2024-03-01T00:00:00+00:00', '--job-id', '186', '--raw', '--subdir', 'DAGS_FOLDER/test_airbyte.py', '--cfg-path', '/tmp/tmpofksr35w']
[2025-01-08T11:38:27.990+0000] {standard_task_runner.py:105} INFO - Job 186: Subtask test_sources_caches
[2025-01-08T11:38:28.034+0000] {task_command.py:467} INFO - Running <TaskInstance: task_dependency_airbyte_dag.test_sources_caches scheduled__2024-03-01T00:00:00+00:00 [running]> on host 835c07788e84
[2025-01-08T11:38:28.109+0000] {taskinstance.py:3132} INFO - Exporting env vars: AIRFLOW_CTX_DAG_OWNER='***' AIRFLOW_CTX_DAG_ID='task_dependency_airbyte_dag' AIRFLOW_CTX_TASK_ID='test_sources_caches' AIRFLOW_CTX_EXECUTION_DATE='2024-03-01T00:00:00+00:00' AIRFLOW_CTX_TRY_NUMBER='2' AIRFLOW_CTX_DAG_RUN_ID='scheduled__2024-03-01T00:00:00+00:00'
[2025-01-08T11:38:28.110+0000] {taskinstance.py:731} INFO - ::endgroup::
[2025-01-08T11:38:28.128+0000] {baseoperator.py:421} WARNING - PythonVirtualenvOperator.execute cannot be called outside TaskInstance!
[2025-01-08T11:38:28.129+0000] {process_utils.py:186} INFO - Executing cmd: /home/***/.local/bin/python -m virtualenv /tmp/venvkv014zo6 --python=python3.10
[2025-01-08T11:38:28.130+0000] {process_utils.py:190} INFO - Output:
[2025-01-08T11:38:28.794+0000] {process_utils.py:194} INFO - RuntimeError: failed to find interpreter for Builtin discover of python_spec='python3.10'
[2025-01-08T11:38:28.817+0000] {taskinstance.py:3311} ERROR - Task failed with exception
Traceback (most recent call last):
  File "/home/airflow/.local/lib/python3.12/site-packages/airflow/models/taskinstance.py", line 767, in _execute_task
    result = _execute_callable(context=context, **execute_callable_kwargs)
             ^^^^^^^^^^^^^^^^^^^^^^^^^^^^^^^^^^^^^^^^^^^^^^^^^^^^^^^^^^^^^
  File "/home/airflow/.local/lib/python3.12/site-packages/airflow/models/taskinstance.py", line 733, in _execute_callable
    return ExecutionCallableRunner(
           ^^^^^^^^^^^^^^^^^^^^^^^^
  File "/home/airflow/.local/lib/python3.12/site-packages/airflow/utils/operator_helpers.py", line 252, in run
    return self.func(*args, **kwargs)
           ^^^^^^^^^^^^^^^^^^^^^^^^^^
  File "/home/airflow/.local/lib/python3.12/site-packages/airflow/models/baseoperator.py", line 422, in wrapper
    return func(self, *args, **kwargs)
           ^^^^^^^^^^^^^^^^^^^^^^^^^^^
  File "/home/airflow/.local/lib/python3.12/site-packages/airflow/operators/python.py", line 505, in execute
    return super().execute(context=serializable_context)
           ^^^^^^^^^^^^^^^^^^^^^^^^^^^^^^^^^^^^^^^^^^^^^
  File "/home/airflow/.local/lib/python3.12/site-packages/airflow/models/baseoperator.py", line 422, in wrapper
    return func(self, *args, **kwargs)
           ^^^^^^^^^^^^^^^^^^^^^^^^^^^
  File "/home/airflow/.local/lib/python3.12/site-packages/airflow/operators/python.py", line 238, in execute
    return_value = self.execute_callable()
                   ^^^^^^^^^^^^^^^^^^^^^^^
  File "/home/airflow/.local/lib/python3.12/site-packages/airflow/operators/python.py", line 868, in execute_callable
    self._prepare_venv(tmp_path)
  File "/home/airflow/.local/lib/python3.12/site-packages/airflow/operators/python.py", line 769, in _prepare_venv
    prepare_virtualenv(
  File "/home/airflow/.local/lib/python3.12/site-packages/airflow/utils/python_virtualenv.py", line 105, in prepare_virtualenv
    execute_in_subprocess(virtualenv_cmd)
  File "/home/airflow/.local/lib/python3.12/site-packages/airflow/utils/process_utils.py", line 175, in execute_in_subprocess
    execute_in_subprocess_with_kwargs(cmd, cwd=cwd, env=env)
  File "/home/airflow/.local/lib/python3.12/site-packages/airflow/utils/process_utils.py", line 198, in execute_in_subprocess_with_kwargs
    raise subprocess.CalledProcessError(exit_code, cmd)
subprocess.CalledProcessError: Command '['/home/airflow/.local/bin/python', '-m', 'virtualenv', '/tmp/venvkv014zo6', '--python=python3.10']' returned non-zero exit status 1.
[2025-01-08T11:38:28.825+0000] {taskinstance.py:1225} INFO - Marking task as FAILED. dag_id=task_dependency_airbyte_dag, task_id=test_sources_caches, run_id=scheduled__2024-03-01T00:00:00+00:00, execution_date=20240301T000000, start_date=20250108T113827, end_date=20250108T113828
[2025-01-08T11:38:28.837+0000] {taskinstance.py:340} INFO - ::group::Post task execution logs
[2025-01-08T11:38:28.838+0000] {standard_task_runner.py:124} ERROR - Failed to execute job 186 for task test_sources_caches (Command '['/home/airflow/.local/bin/python', '-m', 'virtualenv', '/tmp/venvkv014zo6', '--python=python3.10']' returned non-zero exit status 1.; 9147)
Traceback (most recent call last):
  File "/home/airflow/.local/lib/python3.12/site-packages/airflow/task/task_runner/standard_task_runner.py", line 117, in _start_by_fork
    ret = args.func(args, dag=self.dag)
          ^^^^^^^^^^^^^^^^^^^^^^^^^^^^^
  File "/home/airflow/.local/lib/python3.12/site-packages/airflow/cli/cli_config.py", line 49, in command
    return func(*args, **kwargs)
           ^^^^^^^^^^^^^^^^^^^^^
  File "/home/airflow/.local/lib/python3.12/site-packages/airflow/utils/cli.py", line 116, in wrapper
    return f(*args, **kwargs)
           ^^^^^^^^^^^^^^^^^^
  File "/home/airflow/.local/lib/python3.12/site-packages/airflow/cli/commands/task_command.py", line 483, in task_run
    task_return_code = _run_task_by_selected_method(args, _dag, ti)
                       ^^^^^^^^^^^^^^^^^^^^^^^^^^^^^^^^^^^^^^^^^^^^
  File "/home/airflow/.local/lib/python3.12/site-packages/airflow/cli/commands/task_command.py", line 256, in _run_task_by_selected_method
    return _run_raw_task(args, ti)
           ^^^^^^^^^^^^^^^^^^^^^^^
  File "/home/airflow/.local/lib/python3.12/site-packages/airflow/cli/commands/task_command.py", line 341, in _run_raw_task
    return ti._run_raw_task(
           ^^^^^^^^^^^^^^^^^
  File "/home/airflow/.local/lib/python3.12/site-packages/airflow/utils/session.py", line 97, in wrapper
    return func(*args, session=session, **kwargs)
           ^^^^^^^^^^^^^^^^^^^^^^^^^^^^^^^^^^^^^^
  File "/home/airflow/.local/lib/python3.12/site-packages/airflow/models/taskinstance.py", line 3005, in _run_raw_task
    return _run_raw_task(
           ^^^^^^^^^^^^^^
  File "/home/airflow/.local/lib/python3.12/site-packages/airflow/models/taskinstance.py", line 273, in _run_raw_task
    TaskInstance._execute_task_with_callbacks(
  File "/home/airflow/.local/lib/python3.12/site-packages/airflow/models/taskinstance.py", line 3159, in _execute_task_with_callbacks
    result = self._execute_task(context, task_orig)
             ^^^^^^^^^^^^^^^^^^^^^^^^^^^^^^^^^^^^^^
  File "/home/airflow/.local/lib/python3.12/site-packages/airflow/models/taskinstance.py", line 3183, in _execute_task
    return _execute_task(self, context, task_orig)
           ^^^^^^^^^^^^^^^^^^^^^^^^^^^^^^^^^^^^^^^
  File "/home/airflow/.local/lib/python3.12/site-packages/airflow/models/taskinstance.py", line 767, in _execute_task
    result = _execute_callable(context=context, **execute_callable_kwargs)
             ^^^^^^^^^^^^^^^^^^^^^^^^^^^^^^^^^^^^^^^^^^^^^^^^^^^^^^^^^^^^^
  File "/home/airflow/.local/lib/python3.12/site-packages/airflow/models/taskinstance.py", line 733, in _execute_callable
    return ExecutionCallableRunner(
           ^^^^^^^^^^^^^^^^^^^^^^^^
  File "/home/airflow/.local/lib/python3.12/site-packages/airflow/utils/operator_helpers.py", line 252, in run
    return self.func(*args, **kwargs)
           ^^^^^^^^^^^^^^^^^^^^^^^^^^
  File "/home/airflow/.local/lib/python3.12/site-packages/airflow/models/baseoperator.py", line 422, in wrapper
    return func(self, *args, **kwargs)
           ^^^^^^^^^^^^^^^^^^^^^^^^^^^
  File "/home/airflow/.local/lib/python3.12/site-packages/airflow/operators/python.py", line 505, in execute
    return super().execute(context=serializable_context)
           ^^^^^^^^^^^^^^^^^^^^^^^^^^^^^^^^^^^^^^^^^^^^^
  File "/home/airflow/.local/lib/python3.12/site-packages/airflow/models/baseoperator.py", line 422, in wrapper
    return func(self, *args, **kwargs)
           ^^^^^^^^^^^^^^^^^^^^^^^^^^^
  File "/home/airflow/.local/lib/python3.12/site-packages/airflow/operators/python.py", line 238, in execute
    return_value = self.execute_callable()
                   ^^^^^^^^^^^^^^^^^^^^^^^
  File "/home/airflow/.local/lib/python3.12/site-packages/airflow/operators/python.py", line 868, in execute_callable
    self._prepare_venv(tmp_path)
  File "/home/airflow/.local/lib/python3.12/site-packages/airflow/operators/python.py", line 769, in _prepare_venv
    prepare_virtualenv(
  File "/home/airflow/.local/lib/python3.12/site-packages/airflow/utils/python_virtualenv.py", line 105, in prepare_virtualenv
    execute_in_subprocess(virtualenv_cmd)
  File "/home/airflow/.local/lib/python3.12/site-packages/airflow/utils/process_utils.py", line 175, in execute_in_subprocess
    execute_in_subprocess_with_kwargs(cmd, cwd=cwd, env=env)
  File "/home/airflow/.local/lib/python3.12/site-packages/airflow/utils/process_utils.py", line 198, in execute_in_subprocess_with_kwargs
    raise subprocess.CalledProcessError(exit_code, cmd)
subprocess.CalledProcessError: Command '['/home/airflow/.local/bin/python', '-m', 'virtualenv', '/tmp/venvkv014zo6', '--python=python3.10']' returned non-zero exit status 1.
[2025-01-08T11:38:28.844+0000] {local_task_job_runner.py:266} INFO - Task exited with return code 1
[2025-01-08T11:38:28.863+0000] {taskinstance.py:3895} INFO - 0 downstream tasks scheduled from follow-on schedule check
[2025-01-08T11:38:28.869+0000] {local_task_job_runner.py:245} INFO - ::endgroup::
[2025-01-08T12:01:13.313+0000] {local_task_job_runner.py:123} INFO - ::group::Pre task execution logs
[2025-01-08T12:01:13.332+0000] {taskinstance.py:2613} INFO - Dependencies all met for dep_context=non-requeueable deps ti=<TaskInstance: task_dependency_airbyte_dag.test_sources_caches scheduled__2024-03-01T00:00:00+00:00 [queued]>
[2025-01-08T12:01:13.344+0000] {taskinstance.py:2613} INFO - Dependencies all met for dep_context=requeueable deps ti=<TaskInstance: task_dependency_airbyte_dag.test_sources_caches scheduled__2024-03-01T00:00:00+00:00 [queued]>
[2025-01-08T12:01:13.345+0000] {taskinstance.py:2866} INFO - Starting attempt 2 of 2
[2025-01-08T12:01:13.376+0000] {taskinstance.py:2889} INFO - Executing <Task(PythonVirtualenvOperator): test_sources_caches> on 2024-03-01 00:00:00+00:00
[2025-01-08T12:01:13.387+0000] {logging_mixin.py:190} WARNING - /home/***/.local/lib/python3.12/site-packages/***/task/task_runner/standard_task_runner.py:70 DeprecationWarning: This process (pid=10425) is multi-threaded, use of fork() may lead to deadlocks in the child.
[2025-01-08T12:01:13.389+0000] {standard_task_runner.py:72} INFO - Started process 10433 to run task
[2025-01-08T12:01:13.389+0000] {standard_task_runner.py:104} INFO - Running: ['***', 'tasks', 'run', 'task_dependency_airbyte_dag', 'test_sources_caches', 'scheduled__2024-03-01T00:00:00+00:00', '--job-id', '325', '--raw', '--subdir', 'DAGS_FOLDER/test_airbyte.py', '--cfg-path', '/tmp/tmpzv078t3m']
[2025-01-08T12:01:13.394+0000] {standard_task_runner.py:105} INFO - Job 325: Subtask test_sources_caches
[2025-01-08T12:01:13.485+0000] {task_command.py:467} INFO - Running <TaskInstance: task_dependency_airbyte_dag.test_sources_caches scheduled__2024-03-01T00:00:00+00:00 [running]> on host 835c07788e84
[2025-01-08T12:01:13.619+0000] {taskinstance.py:3132} INFO - Exporting env vars: AIRFLOW_CTX_DAG_OWNER='***' AIRFLOW_CTX_DAG_ID='task_dependency_airbyte_dag' AIRFLOW_CTX_TASK_ID='test_sources_caches' AIRFLOW_CTX_EXECUTION_DATE='2024-03-01T00:00:00+00:00' AIRFLOW_CTX_TRY_NUMBER='2' AIRFLOW_CTX_DAG_RUN_ID='scheduled__2024-03-01T00:00:00+00:00'
[2025-01-08T12:01:13.622+0000] {taskinstance.py:731} INFO - ::endgroup::
[2025-01-08T12:01:13.653+0000] {baseoperator.py:421} WARNING - PythonVirtualenvOperator.execute cannot be called outside TaskInstance!
[2025-01-08T12:01:13.655+0000] {process_utils.py:186} INFO - Executing cmd: /home/***/.local/bin/python -m virtualenv /tmp/venvg6_l4h9a --python=python3.10
[2025-01-08T12:01:13.656+0000] {process_utils.py:190} INFO - Output:
[2025-01-08T12:01:14.579+0000] {process_utils.py:194} INFO - RuntimeError: failed to find interpreter for Builtin discover of python_spec='python3.10'
[2025-01-08T12:01:14.618+0000] {taskinstance.py:3311} ERROR - Task failed with exception
Traceback (most recent call last):
  File "/home/airflow/.local/lib/python3.12/site-packages/airflow/models/taskinstance.py", line 767, in _execute_task
    result = _execute_callable(context=context, **execute_callable_kwargs)
             ^^^^^^^^^^^^^^^^^^^^^^^^^^^^^^^^^^^^^^^^^^^^^^^^^^^^^^^^^^^^^
  File "/home/airflow/.local/lib/python3.12/site-packages/airflow/models/taskinstance.py", line 733, in _execute_callable
    return ExecutionCallableRunner(
           ^^^^^^^^^^^^^^^^^^^^^^^^
  File "/home/airflow/.local/lib/python3.12/site-packages/airflow/utils/operator_helpers.py", line 252, in run
    return self.func(*args, **kwargs)
           ^^^^^^^^^^^^^^^^^^^^^^^^^^
  File "/home/airflow/.local/lib/python3.12/site-packages/airflow/models/baseoperator.py", line 422, in wrapper
    return func(self, *args, **kwargs)
           ^^^^^^^^^^^^^^^^^^^^^^^^^^^
  File "/home/airflow/.local/lib/python3.12/site-packages/airflow/operators/python.py", line 505, in execute
    return super().execute(context=serializable_context)
           ^^^^^^^^^^^^^^^^^^^^^^^^^^^^^^^^^^^^^^^^^^^^^
  File "/home/airflow/.local/lib/python3.12/site-packages/airflow/models/baseoperator.py", line 422, in wrapper
    return func(self, *args, **kwargs)
           ^^^^^^^^^^^^^^^^^^^^^^^^^^^
  File "/home/airflow/.local/lib/python3.12/site-packages/airflow/operators/python.py", line 238, in execute
    return_value = self.execute_callable()
                   ^^^^^^^^^^^^^^^^^^^^^^^
  File "/home/airflow/.local/lib/python3.12/site-packages/airflow/operators/python.py", line 868, in execute_callable
    self._prepare_venv(tmp_path)
  File "/home/airflow/.local/lib/python3.12/site-packages/airflow/operators/python.py", line 769, in _prepare_venv
    prepare_virtualenv(
  File "/home/airflow/.local/lib/python3.12/site-packages/airflow/utils/python_virtualenv.py", line 105, in prepare_virtualenv
    execute_in_subprocess(virtualenv_cmd)
  File "/home/airflow/.local/lib/python3.12/site-packages/airflow/utils/process_utils.py", line 175, in execute_in_subprocess
    execute_in_subprocess_with_kwargs(cmd, cwd=cwd, env=env)
  File "/home/airflow/.local/lib/python3.12/site-packages/airflow/utils/process_utils.py", line 198, in execute_in_subprocess_with_kwargs
    raise subprocess.CalledProcessError(exit_code, cmd)
subprocess.CalledProcessError: Command '['/home/airflow/.local/bin/python', '-m', 'virtualenv', '/tmp/venvg6_l4h9a', '--python=python3.10']' returned non-zero exit status 1.
[2025-01-08T12:01:14.626+0000] {taskinstance.py:1225} INFO - Marking task as FAILED. dag_id=task_dependency_airbyte_dag, task_id=test_sources_caches, run_id=scheduled__2024-03-01T00:00:00+00:00, execution_date=20240301T000000, start_date=20250108T120113, end_date=20250108T120114
[2025-01-08T12:01:14.640+0000] {taskinstance.py:340} INFO - ::group::Post task execution logs
[2025-01-08T12:01:14.640+0000] {standard_task_runner.py:124} ERROR - Failed to execute job 325 for task test_sources_caches (Command '['/home/airflow/.local/bin/python', '-m', 'virtualenv', '/tmp/venvg6_l4h9a', '--python=python3.10']' returned non-zero exit status 1.; 10433)
Traceback (most recent call last):
  File "/home/airflow/.local/lib/python3.12/site-packages/airflow/task/task_runner/standard_task_runner.py", line 117, in _start_by_fork
    ret = args.func(args, dag=self.dag)
          ^^^^^^^^^^^^^^^^^^^^^^^^^^^^^
  File "/home/airflow/.local/lib/python3.12/site-packages/airflow/cli/cli_config.py", line 49, in command
    return func(*args, **kwargs)
           ^^^^^^^^^^^^^^^^^^^^^
  File "/home/airflow/.local/lib/python3.12/site-packages/airflow/utils/cli.py", line 116, in wrapper
    return f(*args, **kwargs)
           ^^^^^^^^^^^^^^^^^^
  File "/home/airflow/.local/lib/python3.12/site-packages/airflow/cli/commands/task_command.py", line 483, in task_run
    task_return_code = _run_task_by_selected_method(args, _dag, ti)
                       ^^^^^^^^^^^^^^^^^^^^^^^^^^^^^^^^^^^^^^^^^^^^
  File "/home/airflow/.local/lib/python3.12/site-packages/airflow/cli/commands/task_command.py", line 256, in _run_task_by_selected_method
    return _run_raw_task(args, ti)
           ^^^^^^^^^^^^^^^^^^^^^^^
  File "/home/airflow/.local/lib/python3.12/site-packages/airflow/cli/commands/task_command.py", line 341, in _run_raw_task
    return ti._run_raw_task(
           ^^^^^^^^^^^^^^^^^
  File "/home/airflow/.local/lib/python3.12/site-packages/airflow/utils/session.py", line 97, in wrapper
    return func(*args, session=session, **kwargs)
           ^^^^^^^^^^^^^^^^^^^^^^^^^^^^^^^^^^^^^^
  File "/home/airflow/.local/lib/python3.12/site-packages/airflow/models/taskinstance.py", line 3005, in _run_raw_task
    return _run_raw_task(
           ^^^^^^^^^^^^^^
  File "/home/airflow/.local/lib/python3.12/site-packages/airflow/models/taskinstance.py", line 273, in _run_raw_task
    TaskInstance._execute_task_with_callbacks(
  File "/home/airflow/.local/lib/python3.12/site-packages/airflow/models/taskinstance.py", line 3159, in _execute_task_with_callbacks
    result = self._execute_task(context, task_orig)
             ^^^^^^^^^^^^^^^^^^^^^^^^^^^^^^^^^^^^^^
  File "/home/airflow/.local/lib/python3.12/site-packages/airflow/models/taskinstance.py", line 3183, in _execute_task
    return _execute_task(self, context, task_orig)
           ^^^^^^^^^^^^^^^^^^^^^^^^^^^^^^^^^^^^^^^
  File "/home/airflow/.local/lib/python3.12/site-packages/airflow/models/taskinstance.py", line 767, in _execute_task
    result = _execute_callable(context=context, **execute_callable_kwargs)
             ^^^^^^^^^^^^^^^^^^^^^^^^^^^^^^^^^^^^^^^^^^^^^^^^^^^^^^^^^^^^^
  File "/home/airflow/.local/lib/python3.12/site-packages/airflow/models/taskinstance.py", line 733, in _execute_callable
    return ExecutionCallableRunner(
           ^^^^^^^^^^^^^^^^^^^^^^^^
  File "/home/airflow/.local/lib/python3.12/site-packages/airflow/utils/operator_helpers.py", line 252, in run
    return self.func(*args, **kwargs)
           ^^^^^^^^^^^^^^^^^^^^^^^^^^
  File "/home/airflow/.local/lib/python3.12/site-packages/airflow/models/baseoperator.py", line 422, in wrapper
    return func(self, *args, **kwargs)
           ^^^^^^^^^^^^^^^^^^^^^^^^^^^
  File "/home/airflow/.local/lib/python3.12/site-packages/airflow/operators/python.py", line 505, in execute
    return super().execute(context=serializable_context)
           ^^^^^^^^^^^^^^^^^^^^^^^^^^^^^^^^^^^^^^^^^^^^^
  File "/home/airflow/.local/lib/python3.12/site-packages/airflow/models/baseoperator.py", line 422, in wrapper
    return func(self, *args, **kwargs)
           ^^^^^^^^^^^^^^^^^^^^^^^^^^^
  File "/home/airflow/.local/lib/python3.12/site-packages/airflow/operators/python.py", line 238, in execute
    return_value = self.execute_callable()
                   ^^^^^^^^^^^^^^^^^^^^^^^
  File "/home/airflow/.local/lib/python3.12/site-packages/airflow/operators/python.py", line 868, in execute_callable
    self._prepare_venv(tmp_path)
  File "/home/airflow/.local/lib/python3.12/site-packages/airflow/operators/python.py", line 769, in _prepare_venv
    prepare_virtualenv(
  File "/home/airflow/.local/lib/python3.12/site-packages/airflow/utils/python_virtualenv.py", line 105, in prepare_virtualenv
    execute_in_subprocess(virtualenv_cmd)
  File "/home/airflow/.local/lib/python3.12/site-packages/airflow/utils/process_utils.py", line 175, in execute_in_subprocess
    execute_in_subprocess_with_kwargs(cmd, cwd=cwd, env=env)
  File "/home/airflow/.local/lib/python3.12/site-packages/airflow/utils/process_utils.py", line 198, in execute_in_subprocess_with_kwargs
    raise subprocess.CalledProcessError(exit_code, cmd)
subprocess.CalledProcessError: Command '['/home/airflow/.local/bin/python', '-m', 'virtualenv', '/tmp/venvg6_l4h9a', '--python=python3.10']' returned non-zero exit status 1.
[2025-01-08T12:01:14.688+0000] {local_task_job_runner.py:266} INFO - Task exited with return code 1
[2025-01-08T12:01:14.709+0000] {taskinstance.py:3895} INFO - 0 downstream tasks scheduled from follow-on schedule check
[2025-01-08T12:01:14.715+0000] {local_task_job_runner.py:245} INFO - ::endgroup::
